Workbook

Sheet Top 25
A2: Top 25 expansion targets
A3: Highest-priority candidates not marked already served. Food-access estimates guide the first outreach and verification round.
A4: Ranking weights | E4: Review as of | H4: Review valid days | J4: Oldest retrieval
B5: Baseline | E5: =TODAY() -> 46316 | H5: 180 | J5: =MIN(DATEVALUE(Data!O2),DATEVALUE(Data!H1531),DATEVALUE(Data!K1021)) -> 46304
A7: Eligible candidates | D7: Matching schools | G7: Top 25 enrollment | J7: Marked served
B8: =COUNTIFS(Data!$H$2051:$H$2550,"Yes") -> 305 | E8: =SUM(Data!$AP$2051:$AP$2550) -> 45 | H8: =SUM(E13:E37) -> 14077 | K8: =COUNTIFS(Data!$H$2051:$H$2550,"Yes",Data!$J$2051:$J$2550,"Yes") -> 0
A9: School type | D9: School level | G9: Sort by | J9: Direction | L9: Contacts: blanks = not provided in source
A10: District | D10: Elementary | G10: Priority score | J10: Descending
A11: =IF(E8=0,"No matching schools. Change the filters above.","Showing "&MIN(25,E8)&" of "&E8&" matching schools not marked served. Select All to reset each filter.") -> Showing 25 of 45 matching schools not marked served. Select All to reset each filter.
A12: Order | B12: School | C12: Type | D12: Economic % | E12: Enrollment | F12: Fresh miles | G12: Resources ≤1mi | H12: Score /85 | I12: Food evidence | J12: Why it needs attention | K12: Review row | L12: Contact no.
A13: =IF($N13=0,"",1) -> 1 | B13: =IF($N13=0,"",INDEX(Data!$B$2051:$B$2550,$N13)) -> Rhawnhurst School | C13: =IF($N13=0,"",INDEX(Data!$C$2051:$C$2550,$N13)) -> District | D13: =IF($N13=0,"",INDEX(Data!$G$2051:$G$2550,$N13)) -> 0.7637 | E13: =IF($N13=0,"",INDEX(Data!$F$2051:$F$2550,$N13)) -> 584 | F13: =IF($N13=0,"",INDEX(Data!$K$2051:$K$2550,$N13)) -> 0.51437216 | G13: =IF($N13=0,"",INDEX(Data!$L$2051:$L$2550,$N13)) -> 0 | H13: =IF($N13=0,"",INDEX(Data!$T$2051:$T$2550,$N13)) -> 64 | I13: =IF($N13=0,"",INDEX(Data!$U$2051:$U$2550,$N13)) -> Listed | J13: =IF($N13=0,"",INDEX(Data!$AA$2051:$AA$2550,$N13)) -> 76% economic need; 0.51 mi fresh access; 0 nearby resources | K13: =IF($N13=0,"",IF(INDEX(Data!$I$2051:$I$2550,$N13)=0,"Add ID","Row "&(INDEX(Data!$I$2051:$I$2550,$N13)+7))) -> Row 254 | L13: =IF($N13=0,"",IF(INDEX(Data!$AN$2051:$AN$2550,$N13)=0,"",IF(INDEX(Data!$U$41:$U$540,INDEX(Data!$AN$2051:$AN$2550,$N13))="","",INDEX(Data!$U$41:$U$540,INDEX(Data!$AN$2051:$AN$2550,$N13))))) -> 215-400-3220 | N13: =IF(COUNTIFS(Data!$AR$2051:$AR$2550,1)=1,MATCH(1,Data!$AR$2051:$AR$2550,0),0) -> 309
A14: =IF($N14=0,"",2) -> 2 | B14: =IF($N14=0,"",INDEX(Data!$B$2051:$B$2550,$N14)) -> Kennedy C. Crossan School | C14: =IF($N14=0,"",INDEX(Data!$C$2051:$C$2550,$N14)) -> District | D14: =IF($N14=0,"",INDEX(Data!$G$2051:$G$2550,$N14)) -> 0.7358 | E14: =IF($N14=0,"",INDEX(Data!$F$2051:$F$2550,$N14)) -> 318 | F14: =IF($N14=0,"",INDEX(Data!$K$2051:$K$2550,$N14)) -> 0.82466884 | G14: =IF($N14=0,"",INDEX(Data!$L$2051:$L$2550,$N14)) -> 2 | H14: =IF($N14=0,"",INDEX(Data!$T$2051:$T$2550,$N14)) -> 57 | I14: =IF($N14=0,"",INDEX(Data!$U$2051:$U$2550,$N14)) -> Listed | J14: =IF($N14=0,"",INDEX(Data!$AA$2051:$AA$2550,$N14)) -> 74% economic need; 0.82 mi fresh access; 2 nearby resources | K14: =IF($N14=0,"",IF(INDEX(Data!$I$2051:$I$2550,$N14)=0,"Add ID","Row "&(INDEX(Data!$I$2051:$I$2550,$N14)+7))) -> Row 163 | L14: =IF($N14=0,"",IF(INDEX(Data!$AN$2051:$AN$2550,$N14)=0,"",IF(INDEX(Data!$U$41:$U$540,INDEX(Data!$AN$2051:$AN$2550,$N14))="","",INDEX(Data!$U$41:$U$540,INDEX(Data!$AN$2051:$AN$2550,$N14))))) -> 215-400-3160 | N14: =IF(COUNTIFS(Data!$AR$2051:$AR$2550,2)=1,MATCH(2,Data!$AR$2051:$AR$2550,0),0) -> 300
A15: =IF($N15=0,"",3) -> 3 | B15: =IF($N15=0,"",INDEX(Data!$B$2051:$B$2550,$N15)) -> Edwin Forrest School | C15: =IF($N15=0,"",INDEX(Data!$C$2051:$C$2550,$N15)) -> District | D15: =IF($N15=0,"",INDEX(Data!$G$2051:$G$2550,$N15)) -> 0.776 | E15: =IF($N15=0,"",INDEX(Data!$F$2051:$F$2550,$N15)) -> 798 | F15: =IF($N15=0,"",INDEX(Data!$K$2051:$K$2550,$N15)) -> 0.77034598 | G15: =IF($N15=0,"",INDEX(Data!$L$2051:$L$2550,$N15)) -> 3 | H15: =IF($N15=0,"",INDEX(Data!$T$2051:$T$2550,$N15)) -> 55 | I15: =IF($N15=0,"",INDEX(Data!$U$2051:$U$2550,$N15)) -> Listed | J15: =IF($N15=0,"",INDEX(Data!$AA$2051:$AA$2550,$N15)) -> 78% economic need; 0.77 mi fresh access; 3 nearby resources | K15: =IF($N15=0,"",IF(INDEX(Data!$I$2051:$I$2550,$N15)=0,"Add ID","Row "&(INDEX(Data!$I$2051:$I$2550,$N15)+7))) -> Row 65 | L15: =IF($N15=0,"",IF(INDEX(Data!$AN$2051:$AN$2550,$N15)=0,"",IF(INDEX(Data!$U$41:$U$540,INDEX(Data!$AN$2051:$AN$2550,$N15))="","",INDEX(Data!$U$41:$U$540,INDEX(Data!$AN$2051:$AN$2550,$N15))))) -> 215-400-3330 | N15: =IF(COUNTIFS(Data!$AR$2051:$AR$2550,3)=1,MATCH(3,Data!$AR$2051:$AR$2550,0),0) -> 302
A16: =IF($N16=0,"",4) -> 4 | B16: =IF($N16=0,"",INDEX(Data!$B$2051:$B$2550,$N16)) -> Fox Chase School | C16: =IF($N16=0,"",INDEX(Data!$C$2051:$C$2550,$N16)) -> District | D16: =IF($N16=0,"",INDEX(Data!$G$2051:$G$2550,$N16)) -> 0.6847 | E16: =IF($N16=0,"",INDEX(Data!$F$2051:$F$2550,$N16)) -> 500 | F16: =IF($N16=0,"",INDEX(Data!$K$2051:$K$2550,$N16)) -> 0.86765672 | G16: =IF($N16=0,"",INDEX(Data!$L$2051:$L$2550,$N16)) -> 2 | H16: =IF($N16=0,"",INDEX(Data!$T$2051:$T$2550,$N16)) -> 54 | I16: =IF($N16=0,"",INDEX(Data!$U$2051:$U$2550,$N16)) -> Listed | J16: =IF($N16=0,"",INDEX(Data!$AA$2051:$AA$2550,$N16)) -> 68% economic need; 0.87 mi fresh access; 2 nearby resources | K16: =IF($N16=0,"",IF(INDEX(Data!$I$2051:$I$2550,$N16)=0,"Add ID","Row "&(INDEX(Data!$I$2051:$I$2550,$N16)+7))) -> Row 85 | L16: =IF($N16=0,"",IF(INDEX(Data!$AN$2051:$AN$2550,$N16)=0,"",IF(INDEX(Data!$U$41:$U$540,INDEX(Data!$AN$2051:$AN$2550,$N16))="","",INDEX(Data!$U$41:$U$540,INDEX(Data!$AN$2051:$AN$2550,$N16))))) -> 215-400-3170 | N16: =IF(COUNTIFS(Data!$AR$2051:$AR$2550,4)=1,MATCH(4,Data!$AR$2051:$AR$2550,0),0) -> 303
A17: =IF($N17=0,"",5) -> 5 | B17: =IF($N17=0,"",INDEX(Data!$B$2051:$B$2550,$N17)) -> John M. Patterson School | C17: =IF($N17=0,"",INDEX(Data!$C$2051:$C$2550,$N17)) -> District | D17: =IF($N17=0,"",INDEX(Data!$G$2051:$G$2550,$N17)) -> 0.8425 | E17: =IF($N17=0,"",INDEX(Data!$F$2051:$F$2550,$N17)) -> 353 | F17: =IF($N17=0,"",INDEX(Data!$K$2051:$K$2550,$N17)) -> 0.73087419 | G17: =IF($N17=0,"",INDEX(Data!$L$2051:$L$2550,$N17)) -> 3 | H17: =IF($N17=0,"",INDEX(Data!$T$2051:$T$2550,$N17)) -> 53 | I17: =IF($N17=0,"",INDEX(Data!$U$2051:$U$2550,$N17)) -> Listed | J17: =IF($N17=0,"",INDEX(Data!$AA$2051:$AA$2550,$N17)) -> 84% economic need; 0.73 mi fresh access; 3 nearby resources | K17: =IF($N17=0,"",IF(INDEX(Data!$I$2051:$I$2550,$N17)=0,"Add ID","Row "&(INDEX(Data!$I$2051:$I$2550,$N17)+7))) -> Row 148 | L17: =IF($N17=0,"",IF(INDEX(Data!$AN$2051:$AN$2550,$N17)=0,"",IF(INDEX(Data!$U$41:$U$540,INDEX(Data!$AN$2051:$AN$2550,$N17))="","",INDEX(Data!$U$41:$U$540,INDEX(Data!$AN$2051:$AN$2550,$N17))))) -> 215-400-8190 | N17: =IF(COUNTIFS(Data!$AR$2051:$AR$2550,5)=1,MATCH(5,Data!$AR$2051:$AR$2550,0),0) -> 21
A18: =IF($N18=0,"",6) -> 6 | B18: =IF($N18=0,"",INDEX(Data!$B$2051:$B$2550,$N18)) -> J. Hampton Moore School | C18: =IF($N18=0,"",INDEX(Data!$C$2051:$C$2550,$N18)) -> District | D18: =IF($N18=0,"",INDEX(Data!$G$2051:$G$2550,$N18)) -> 0.7795 | E18: =IF($N18=0,"",INDEX(Data!$F$2051:$F$2550,$N18)) -> 1162 | F18: =IF($N18=0,"",INDEX(Data!$K$2051:$K$2550,$N18)) -> 0.48677922 | G18: =IF($N18=0,"",INDEX(Data!$L$2051:$L$2550,$N18)) -> 2 | H18: =IF($N18=0,"",INDEX(Data!$T$2051:$T$2550,$N18)) -> 50 | I18: =IF($N18=0,"",INDEX(Data!$U$2051:$U$2550,$N18)) -> Listed | J18: =IF($N18=0,"",INDEX(Data!$AA$2051:$AA$2550,$N18)) -> 78% economic need; 0.49 mi fresh access; 2 nearby resources | K18: =IF($N18=0,"",IF(INDEX(Data!$I$2051:$I$2550,$N18)=0,"Add ID","Row "&(INDEX(Data!$I$2051:$I$2550,$N18)+7))) -> Row 131 | L18: =IF($N18=0,"",IF(INDEX(Data!$AN$2051:$AN$2550,$N18)=0,"",IF(INDEX(Data!$U$41:$U$540,INDEX(Data!$AN$2051:$AN$2550,$N18))="","",INDEX(Data!$U$41:$U$540,INDEX(Data!$AN$2051:$AN$2550,$N18))))) -> 215-400-3180 | N18: =IF(COUNTIFS(Data!$AR$2051:$AR$2550,6)=1,MATCH(6,Data!$AR$2051:$AR$2550,0),0) -> 306
A19: =IF($N19=0,"",7) -> 7 | B19: =IF($N19=0,"",INDEX(Data!$B$2051:$B$2550,$N19)) -> Henry W. Lawton School | C19: =IF($N19=0,"",INDEX(Data!$C$2051:$C$2550,$N19)) -> District | D19: =IF($N19=0,"",INDEX(Data!$G$2051:$G$2550,$N19)) -> 0.8275 | E19: =IF($N19=0,"",INDEX(Data!$F$2051:$F$2550,$N19)) -> 513 | F19: =IF($N19=0,"",INDEX(Data!$K$2051:$K$2550,$N19)) -> 0.36615105 | G19: =IF($N19=0,"",INDEX(Data!$L$2051:$L$2550,$N19)) -> 3 | H19: =IF($N19=0,"",INDEX(Data!$T$2051:$T$2550,$N19)) -> 49 | I19: =IF($N19=0,"",INDEX(Data!$U$2051:$U$2550,$N19)) -> Listed | J19: =IF($N19=0,"",INDEX(Data!$AA$2051:$AA$2550,$N19)) -> 83% economic need; 0.37 mi fresh access; 3 nearby resources | K19: =IF($N19=0,"",IF(INDEX(Data!$I$2051:$I$2550,$N19)=0,"Add ID","Row "&(INDEX(Data!$I$2051:$I$2550,$N19)+7))) -> Row 119 | L19: =IF($N19=0,"",IF(INDEX(Data!$AN$2051:$AN$2550,$N19)=0,"",IF(INDEX(Data!$U$41:$U$540,INDEX(Data!$AN$2051:$AN$2550,$N19))="","",INDEX(Data!$U$41:$U$540,INDEX(Data!$AN$2051:$AN$2550,$N19))))) -> 215-400-3340 | N19: =IF(COUNTIFS(Data!$AR$2051:$AR$2550,7)=1,MATCH(7,Data!$AR$2051:$AR$2550,0),0) -> 270
A20: =IF($N20=0,"",8) -> 8 | B20: =IF($N20=0,"",INDEX(Data!$B$2051:$B$2550,$N20)) -> Watson Comly School | C20: =IF($N20=0,"",INDEX(Data!$C$2051:$C$2550,$N20)) -> District | D20: =IF($N20=0,"",INDEX(Data!$G$2051:$G$2550,$N20)) -> 0.6656 | E20: =IF($N20=0,"",INDEX(Data!$F$2051:$F$2550,$N20)) -> 660 | F20: =IF($N20=0,"",INDEX(Data!$K$2051:$K$2550,$N20)) -> 0.42671827 | G20: =IF($N20=0,"",INDEX(Data!$L$2051:$L$2550,$N20)) -> 1 | H20: =IF($N20=0,"",INDEX(Data!$T$2051:$T$2550,$N20)) -> 49 | I20: =IF($N20=0,"",INDEX(Data!$U$2051:$U$2550,$N20)) -> Listed | J20: =IF($N20=0,"",INDEX(Data!$AA$2051:$AA$2550,$N20)) -> 67% economic need; 0.43 mi fresh access; 1 nearby resources | K20: =IF($N20=0,"",IF(INDEX(Data!$I$2051:$I$2550,$N20)=0,"Add ID","Row "&(INDEX(Data!$I$2051:$I$2550,$N20)+7))) -> Row 314 | L20: =IF($N20=0,"",IF(INDEX(Data!$AN$2051:$AN$2550,$N20)=0,"",IF(INDEX(Data!$U$41:$U$540,INDEX(Data!$AN$2051:$AN$2550,$N20))="","",INDEX(Data!$U$41:$U$540,INDEX(Data!$AN$2051:$AN$2550,$N20))))) -> 215-400-3010 | N20: =IF(COUNTIFS(Data!$AR$2051:$AR$2550,8)=1,MATCH(8,Data!$AR$2051:$AR$2550,0),0) -> 310
A21: =IF($N21=0,"",9) -> 9 | B21: =IF($N21=0,"",INDEX(Data!$B$2051:$B$2550,$N21)) -> Frances E. Willard School | C21: =IF($N21=0,"",INDEX(Data!$C$2051:$C$2550,$N21)) -> District | D21: =IF($N21=0,"",INDEX(Data!$G$2051:$G$2550,$N21)) -> 0.9342 | E21: =IF($N21=0,"",INDEX(Data!$F$2051:$F$2550,$N21)) -> 352 | F21: =IF($N21=0,"",INDEX(Data!$K$2051:$K$2550,$N21)) -> 0.64030942 | G21: =IF($N21=0,"",INDEX(Data!$L$2051:$L$2550,$N21)) -> 12 | H21: =IF($N21=0,"",INDEX(Data!$T$2051:$T$2550,$N21)) -> 48 | I21: =IF($N21=0,"",INDEX(Data!$U$2051:$U$2550,$N21)) -> Listed | J21: =IF($N21=0,"",INDEX(Data!$AA$2051:$AA$2550,$N21)) -> 93% economic need; 0.64 mi fresh access; 12 nearby resources | K21: =IF($N21=0,"",IF(INDEX(Data!$I$2051:$I$2550,$N21)=0,"Add ID","Row "&(INDEX(Data!$I$2051:$I$2550,$N21)+7))) -> Row 86 | L21: =IF($N21=0,"",IF(INDEX(Data!$AN$2051:$AN$2550,$N21)=0,"",IF(INDEX(Data!$U$41:$U$540,INDEX(Data!$AN$2051:$AN$2550,$N21))="","",INDEX(Data!$U$41:$U$540,INDEX(Data!$AN$2051:$AN$2550,$N21))))) -> 215-400-7180 | N21: =IF(COUNTIFS(Data!$AR$2051:$AR$2550,9)=1,MATCH(9,Data!$AR$2051:$AR$2550,0),0) -> 205
A22: =IF($N22=0,"",10) -> 10 | B22: =IF($N22=0,"",INDEX(Data!$B$2051:$B$2550,$N22)) -> James R. Lowell School | C22: =IF($N22=0,"",INDEX(Data!$C$2051:$C$2550,$N22)) -> District | D22: =IF($N22=0,"",INDEX(Data!$G$2051:$G$2550,$N22)) -> 0.8768 | E22: =IF($N22=0,"",INDEX(Data!$F$2051:$F$2550,$N22)) -> 430 | F22: =IF($N22=0,"",INDEX(Data!$K$2051:$K$2550,$N22)) -> 0.54540436 | G22: =IF($N22=0,"",INDEX(Data!$L$2051:$L$2550,$N22)) -> 4 | H22: =IF($N22=0,"",INDEX(Data!$T$2051:$T$2550,$N22)) -> 48 | I22: =IF($N22=0,"",INDEX(Data!$U$2051:$U$2550,$N22)) -> Listed | J22: =IF($N22=0,"",INDEX(Data!$AA$2051:$AA$2550,$N22)) -> 88% economic need; 0.55 mi fresh access; 4 nearby resources | K22: =IF($N22=0,"",IF(INDEX(Data!$I$2051:$I$2550,$N22)=0,"Add ID","Row "&(INDEX(Data!$I$2051:$I$2550,$N22)+7))) -> Row 136 | L22: =IF($N22=0,"",IF(INDEX(Data!$AN$2051:$AN$2550,$N22)=0,"",IF(INDEX(Data!$U$41:$U$540,INDEX(Data!$AN$2051:$AN$2550,$N22))="","",INDEX(Data!$U$41:$U$540,INDEX(Data!$AN$2051:$AN$2550,$N22))))) -> 215-400-3740 | N22: =IF(COUNTIFS(Data!$AR$2051:$AR$2550,10)=1,MATCH(10,Data!$AR$2051:$AR$2550,0),0) -> 271
A23: =IF($N23=0,"",11) -> 11 | B23: =IF($N23=0,"",INDEX(Data!$B$2051:$B$2550,$N23)) -> James Logan School | C23: =IF($N23=0,"",INDEX(Data!$C$2051:$C$2550,$N23)) -> District | D23: =IF($N23=0,"",INDEX(Data!$G$2051:$G$2550,$N23)) -> 0.9023 | E23: =IF($N23=0,"",INDEX(Data!$F$2051:$F$2550,$N23)) -> 223 | F23: =IF($N23=0,"",INDEX(Data!$K$2051:$K$2550,$N23)) -> 0.69701528 | G23: =IF($N23=0,"",INDEX(Data!$L$2051:$L$2550,$N23)) -> 8 | H23: =IF($N23=0,"",INDEX(Data!$T$2051:$T$2550,$N23)) -> 47 | I23: =IF($N23=0,"",INDEX(Data!$U$2051:$U$2550,$N23)) -> Listed | J23: =IF($N23=0,"",INDEX(Data!$AA$2051:$AA$2550,$N23)) -> 90% economic need; 0.70 mi fresh access; 8 nearby resources | K23: =IF($N23=0,"",IF(INDEX(Data!$I$2051:$I$2550,$N23)=0,"Add ID","Row "&(INDEX(Data!$I$2051:$I$2550,$N23)+7))) -> Row 135 | L23: =IF($N23=0,"",IF(INDEX(Data!$AN$2051:$AN$2550,$N23)=0,"",IF(INDEX(Data!$U$41:$U$540,INDEX(Data!$AN$2051:$AN$2550,$N23))="","",INDEX(Data!$U$41:$U$540,INDEX(Data!$AN$2051:$AN$2550,$N23))))) -> 215-400-3670 | N23: =IF(COUNTIFS(Data!$AR$2051:$AR$2550,11)=1,MATCH(11,Data!$AR$2051:$AR$2550,0),0) -> 236
A24: =IF($N24=0,"",12) -> 12 | B24: =IF($N24=0,"",INDEX(Data!$B$2051:$B$2550,$N24)) -> Solomon Solis-Cohen School | C24: =IF($N24=0,"",INDEX(Data!$C$2051:$C$2550,$N24)) -> District | D24: =IF($N24=0,"",INDEX(Data!$G$2051:$G$2550,$N24)) -> 0.7902 | E24: =IF($N24=0,"",INDEX(Data!$F$2051:$F$2550,$N24)) -> 1354 | F24: =IF($N24=0,"",INDEX(Data!$K$2051:$K$2550,$N24)) -> 0.36391859 | G24: =IF($N24=0,"",INDEX(Data!$L$2051:$L$2550,$N24)) -> 3 | H24: =IF($N24=0,"",INDEX(Data!$T$2051:$T$2550,$N24)) -> 45 | I24: =IF($N24=0,"",INDEX(Data!$U$2051:$U$2550,$N24)) -> Listed | J24: =IF($N24=0,"",INDEX(Data!$AA$2051:$AA$2550,$N24)) -> 79% economic need; 0.36 mi fresh access; 3 nearby resources | K24: =IF($N24=0,"",IF(INDEX(Data!$I$2051:$I$2550,$N24)=0,"Add ID","Row "&(INDEX(Data!$I$2051:$I$2550,$N24)+7))) -> Row 276 | L24: =IF($N24=0,"",IF(INDEX(Data!$AN$2051:$AN$2550,$N24)=0,"",IF(INDEX(Data!$U$41:$U$540,INDEX(Data!$AN$2051:$AN$2550,$N24))="","",INDEX(Data!$U$41:$U$540,INDEX(Data!$AN$2051:$AN$2550,$N24))))) -> 215-400-3250 | N24: =IF(COUNTIFS(Data!$AR$2051:$AR$2550,12)=1,MATCH(12,Data!$AR$2051:$AR$2550,0),0) -> 307
A25: =IF($N25=0,"",13) -> 13 | B25: =IF($N25=0,"",INDEX(Data!$B$2051:$B$2550,$N25)) -> Anne Frank School | C25: =IF($N25=0,"",INDEX(Data!$C$2051:$C$2550,$N25)) -> District | D25: =IF($N25=0,"",INDEX(Data!$G$2051:$G$2550,$N25)) -> 0.6848 | E25: =IF($N25=0,"",INDEX(Data!$F$2051:$F$2550,$N25)) -> 1687 | F25: =IF($N25=0,"",INDEX(Data!$K$2051:$K$2550,$N25)) -> 0.3258615 | G25: =IF($N25=0,"",INDEX(Data!$L$2051:$L$2550,$N25)) -> 2 | H25: =IF($N25=0,"",INDEX(Data!$T$2051:$T$2550,$N25)) -> 45 | I25: =IF($N25=0,"",INDEX(Data!$U$2051:$U$2550,$N25)) -> Listed | J25: =IF($N25=0,"",INDEX(Data!$AA$2051:$AA$2550,$N25)) -> 68% economic need; 0.33 mi fresh access; 2 nearby resources | K25: =IF($N25=0,"",IF(INDEX(Data!$I$2051:$I$2550,$N25)=0,"Add ID","Row "&(INDEX(Data!$I$2051:$I$2550,$N25)+7))) -> Row 29 | L25: =IF($N25=0,"",IF(INDEX(Data!$AN$2051:$AN$2550,$N25)=0,"",IF(INDEX(Data!$U$41:$U$540,INDEX(Data!$AN$2051:$AN$2550,$N25))="","",INDEX(Data!$U$41:$U$540,INDEX(Data!$AN$2051:$AN$2550,$N25))))) -> 215-400-3070 | N25: =IF(COUNTIFS(Data!$AR$2051:$AR$2550,13)=1,MATCH(13,Data!$AR$2051:$AR$2550,0),0) -> 313
A26: =IF($N26=0,"",14) -> 14 | B26: =IF($N26=0,"",INDEX(Data!$B$2051:$B$2550,$N26)) -> Lewis Elkin School | C26: =IF($N26=0,"",INDEX(Data!$C$2051:$C$2550,$N26)) -> District | D26: =IF($N26=0,"",INDEX(Data!$G$2051:$G$2550,$N26)) -> 0.9069 | E26: =IF($N26=0,"",INDEX(Data!$F$2051:$F$2550,$N26)) -> 431 | F26: =IF($N26=0,"",INDEX(Data!$K$2051:$K$2550,$N26)) -> 0.32714422 | G26: =IF($N26=0,"",INDEX(Data!$L$2051:$L$2550,$N26)) -> 10 | H26: =IF($N26=0,"",INDEX(Data!$T$2051:$T$2550,$N26)) -> 43 | I26: =IF($N26=0,"",INDEX(Data!$U$2051:$U$2550,$N26)) -> Listed | J26: =IF($N26=0,"",INDEX(Data!$AA$2051:$AA$2550,$N26)) -> 91% economic need; 0.33 mi fresh access; 10 nearby resources | K26: =IF($N26=0,"",IF(INDEX(Data!$I$2051:$I$2550,$N26)=0,"Add ID","Row "&(INDEX(Data!$I$2051:$I$2550,$N26)+7))) -> Row 178 | L26: =IF($N26=0,"",IF(INDEX(Data!$AN$2051:$AN$2550,$N26)=0,"",IF(INDEX(Data!$U$41:$U$540,INDEX(Data!$AN$2051:$AN$2550,$N26))="","",INDEX(Data!$U$41:$U$540,INDEX(Data!$AN$2051:$AN$2550,$N26))))) -> 215-400-7140 | N26: =IF(COUNTIFS(Data!$AR$2051:$AR$2550,14)=1,MATCH(14,Data!$AR$2051:$AR$2550,0),0) -> 193
A27: =IF($N27=0,"",15) -> 15 | B27: =IF($N27=0,"",INDEX(Data!$B$2051:$B$2550,$N27)) -> Thomas M. Peirce School | C27: =IF($N27=0,"",INDEX(Data!$C$2051:$C$2550,$N27)) -> District | D27: =IF($N27=0,"",INDEX(Data!$G$2051:$G$2550,$N27)) -> 0.9375 | E27: =IF($N27=0,"",INDEX(Data!$F$2051:$F$2550,$N27)) -> 292 | F27: =IF($N27=0,"",INDEX(Data!$K$2051:$K$2550,$N27)) -> 0.26794265 | G27: =IF($N27=0,"",INDEX(Data!$L$2051:$L$2550,$N27)) -> 12 | H27: =IF($N27=0,"",INDEX(Data!$T$2051:$T$2550,$N27)) -> 42 | I27: =IF($N27=0,"",INDEX(Data!$U$2051:$U$2550,$N27)) -> Listed | J27: =IF($N27=0,"",INDEX(Data!$AA$2051:$AA$2550,$N27)) -> 94% economic need; 0.27 mi fresh access; 12 nearby resources | K27: =IF($N27=0,"",IF(INDEX(Data!$I$2051:$I$2550,$N27)=0,"Add ID","Row "&(INDEX(Data!$I$2051:$I$2550,$N27)+7))) -> Row 303 | L27: =IF($N27=0,"",IF(INDEX(Data!$AN$2051:$AN$2550,$N27)=0,"",IF(INDEX(Data!$U$41:$U$540,INDEX(Data!$AN$2051:$AN$2550,$N27))="","",INDEX(Data!$U$41:$U$540,INDEX(Data!$AN$2051:$AN$2550,$N27))))) -> 215-400-7020 | N27: =IF(COUNTIFS(Data!$AR$2051:$AR$2550,15)=1,MATCH(15,Data!$AR$2051:$AR$2550,0),0) -> 170
A28: =IF($N28=0,"",16) -> 16 | B28: =IF($N28=0,"",INDEX(Data!$B$2051:$B$2550,$N28)) -> Prince Hall School | C28: =IF($N28=0,"",INDEX(Data!$C$2051:$C$2550,$N28)) -> District | D28: =IF($N28=0,"",INDEX(Data!$G$2051:$G$2550,$N28)) -> 0.9169 | E28: =IF($N28=0,"",INDEX(Data!$F$2051:$F$2550,$N28)) -> 317 | F28: =IF($N28=0,"",INDEX(Data!$K$2051:$K$2550,$N28)) -> 0.35373086 | G28: =IF($N28=0,"",INDEX(Data!$L$2051:$L$2550,$N28)) -> 12 | H28: =IF($N28=0,"",INDEX(Data!$T$2051:$T$2550,$N28)) -> 42 | I28: =IF($N28=0,"",INDEX(Data!$U$2051:$U$2550,$N28)) -> Listed | J28: =IF($N28=0,"",INDEX(Data!$AA$2051:$AA$2550,$N28)) -> 92% economic need; 0.35 mi fresh access; 12 nearby resources | K28: =IF($N28=0,"",IF(INDEX(Data!$I$2051:$I$2550,$N28)=0,"Add ID","Row "&(INDEX(Data!$I$2051:$I$2550,$N28)+7))) -> Row 252 | L28: =IF($N28=0,"",IF(INDEX(Data!$AN$2051:$AN$2550,$N28)=0,"",IF(INDEX(Data!$U$41:$U$540,INDEX(Data!$AN$2051:$AN$2550,$N28))="","",INDEX(Data!$U$41:$U$540,INDEX(Data!$AN$2051:$AN$2550,$N28))))) -> 215-400-3690 | N28: =IF(COUNTIFS(Data!$AR$2051:$AR$2550,16)=1,MATCH(16,Data!$AR$2051:$AR$2550,0),0) -> 281
A29: =IF($N29=0,"",17) -> 17 | B29: =IF($N29=0,"",INDEX(Data!$B$2051:$B$2550,$N29)) -> William Cramp School | C29: =IF($N29=0,"",INDEX(Data!$C$2051:$C$2550,$N29)) -> District | D29: =IF($N29=0,"",INDEX(Data!$G$2051:$G$2550,$N29)) -> 0.9028 | E29: =IF($N29=0,"",INDEX(Data!$F$2051:$F$2550,$N29)) -> 317 | F29: =IF($N29=0,"",INDEX(Data!$K$2051:$K$2550,$N29)) -> 0.33933365 | G29: =IF($N29=0,"",INDEX(Data!$L$2051:$L$2550,$N29)) -> 13 | H29: =IF($N29=0,"",INDEX(Data!$T$2051:$T$2550,$N29)) -> 42 | I29: =IF($N29=0,"",INDEX(Data!$U$2051:$U$2550,$N29)) -> Listed | J29: =IF($N29=0,"",INDEX(Data!$AA$2051:$AA$2550,$N29)) -> 90% economic need; 0.34 mi fresh access; 13 nearby resources | K29: =IF($N29=0,"",IF(INDEX(Data!$I$2051:$I$2550,$N29)=0,"Add ID","Row "&(INDEX(Data!$I$2051:$I$2550,$N29)+7))) -> Row 321 | L29: =IF($N29=0,"",IF(INDEX(Data!$AN$2051:$AN$2550,$N29)=0,"",IF(INDEX(Data!$U$41:$U$540,INDEX(Data!$AN$2051:$AN$2550,$N29))="","",INDEX(Data!$U$41:$U$540,INDEX(Data!$AN$2051:$AN$2550,$N29))))) -> 215-400-3860 | N29: =IF(COUNTIFS(Data!$AR$2051:$AR$2550,17)=1,MATCH(17,Data!$AR$2051:$AR$2550,0),0) -> 206
A30: =IF($N30=0,"",18) -> 18 | B30: =IF($N30=0,"",INDEX(Data!$B$2051:$B$2550,$N30)) -> John B. Kelly School | C30: =IF($N30=0,"",INDEX(Data!$C$2051:$C$2550,$N30)) -> District | D30: =IF($N30=0,"",INDEX(Data!$G$2051:$G$2550,$N30)) -> 0.8699 | E30: =IF($N30=0,"",INDEX(Data!$F$2051:$F$2550,$N30)) -> 346 | F30: =IF($N30=0,"",INDEX(Data!$K$2051:$K$2550,$N30)) -> 0.63546307 | G30: =IF($N30=0,"",INDEX(Data!$L$2051:$L$2550,$N30)) -> 11 | H30: =IF($N30=0,"",INDEX(Data!$T$2051:$T$2550,$N30)) -> 42 | I30: =IF($N30=0,"",INDEX(Data!$U$2051:$U$2550,$N30)) -> Listed | J30: =IF($N30=0,"",INDEX(Data!$AA$2051:$AA$2550,$N30)) -> 87% economic need; 0.64 mi fresh access; 11 nearby resources | K30: =IF($N30=0,"",IF(INDEX(Data!$I$2051:$I$2550,$N30)=0,"Add ID","Row "&(INDEX(Data!$I$2051:$I$2550,$N30)+7))) -> Row 140 | L30: =IF($N30=0,"",IF(INDEX(Data!$AN$2051:$AN$2550,$N30)=0,"",IF(INDEX(Data!$U$41:$U$540,INDEX(Data!$AN$2051:$AN$2550,$N30))="","",INDEX(Data!$U$41:$U$540,INDEX(Data!$AN$2051:$AN$2550,$N30))))) -> 215-400-3580 | N30: =IF(COUNTIFS(Data!$AR$2051:$AR$2550,18)=1,MATCH(18,Data!$AR$2051:$AR$2550,0),0) -> 249
A31: =IF($N31=0,"",19) -> 19 | B31: =IF($N31=0,"",INDEX(Data!$B$2051:$B$2550,$N31)) -> John Marshall School | C31: =IF($N31=0,"",INDEX(Data!$C$2051:$C$2550,$N31)) -> District | D31: =IF($N31=0,"",INDEX(Data!$G$2051:$G$2550,$N31)) -> 0.8641 | E31: =IF($N31=0,"",INDEX(Data!$F$2051:$F$2550,$N31)) -> 243 | F31: =IF($N31=0,"",INDEX(Data!$K$2051:$K$2550,$N31)) -> 0.57437948 | G31: =IF($N31=0,"",INDEX(Data!$L$2051:$L$2550,$N31)) -> 7 | H31: =IF($N31=0,"",INDEX(Data!$T$2051:$T$2550,$N31)) -> 42 | I31: =IF($N31=0,"",INDEX(Data!$U$2051:$U$2550,$N31)) -> Listed | J31: =IF($N31=0,"",INDEX(Data!$AA$2051:$AA$2550,$N31)) -> 86% economic need; 0.57 mi fresh access; 7 nearby resources | K31: =IF($N31=0,"",IF(INDEX(Data!$I$2051:$I$2550,$N31)=0,"Add ID","Row "&(INDEX(Data!$I$2051:$I$2550,$N31)+7))) -> Row 149 | L31: =IF($N31=0,"",IF(INDEX(Data!$AN$2051:$AN$2550,$N31)=0,"",IF(INDEX(Data!$U$41:$U$540,INDEX(Data!$AN$2051:$AN$2550,$N31))="","",INDEX(Data!$U$41:$U$540,INDEX(Data!$AN$2051:$AN$2550,$N31))))) -> 215-400-3950 | N31: =IF(COUNTIFS(Data!$AR$2051:$AR$2550,19)=1,MATCH(19,Data!$AR$2051:$AR$2550,0),0) -> 272
A32: =IF($N32=0,"",20) -> 20 | B32: =IF($N32=0,"",INDEX(Data!$B$2051:$B$2550,$N32)) -> William Rowen School | C32: =IF($N32=0,"",INDEX(Data!$C$2051:$C$2550,$N32)) -> District | D32: =IF($N32=0,"",INDEX(Data!$G$2051:$G$2550,$N32)) -> 0.8357 | E32: =IF($N32=0,"",INDEX(Data!$F$2051:$F$2550,$N32)) -> 272 | F32: =IF($N32=0,"",INDEX(Data!$K$2051:$K$2550,$N32)) -> 0.69579035 | G32: =IF($N32=0,"",INDEX(Data!$L$2051:$L$2550,$N32)) -> 9 | H32: =IF($N32=0,"",INDEX(Data!$T$2051:$T$2550,$N32)) -> 42 | I32: =IF($N32=0,"",INDEX(Data!$U$2051:$U$2550,$N32)) -> Listed | J32: =IF($N32=0,"",INDEX(Data!$AA$2051:$AA$2550,$N32)) -> 84% economic need; 0.70 mi fresh access; 9 nearby resources | K32: =IF($N32=0,"",IF(INDEX(Data!$I$2051:$I$2550,$N32)=0,"Add ID","Row "&(INDEX(Data!$I$2051:$I$2550,$N32)+7))) -> Row 330 | L32: =IF($N32=0,"",IF(INDEX(Data!$AN$2051:$AN$2550,$N32)=0,"",IF(INDEX(Data!$U$41:$U$540,INDEX(Data!$AN$2051:$AN$2550,$N32))="","",INDEX(Data!$U$41:$U$540,INDEX(Data!$AN$2051:$AN$2550,$N32))))) -> 215-400-3550 | N32: =IF(COUNTIFS(Data!$AR$2051:$AR$2550,20)=1,MATCH(20,Data!$AR$2051:$AR$2550,0),0) -> 284
A33: =IF($N33=0,"",21) -> 21 | B33: =IF($N33=0,"",INDEX(Data!$B$2051:$B$2550,$N33)) -> Richmond School | C33: =IF($N33=0,"",INDEX(Data!$C$2051:$C$2550,$N33)) -> District | D33: =IF($N33=0,"",INDEX(Data!$G$2051:$G$2550,$N33)) -> 0.8192 | E33: =IF($N33=0,"",INDEX(Data!$F$2051:$F$2550,$N33)) -> 332 | F33: =IF($N33=0,"",INDEX(Data!$K$2051:$K$2550,$N33)) -> 0.57120741 | G33: =IF($N33=0,"",INDEX(Data!$L$2051:$L$2550,$N33)) -> 6 | H33: =IF($N33=0,"",INDEX(Data!$T$2051:$T$2550,$N33)) -> 42 | I33: =IF($N33=0,"",INDEX(Data!$U$2051:$U$2550,$N33)) -> Listed | J33: =IF($N33=0,"",INDEX(Data!$AA$2051:$AA$2550,$N33)) -> 82% economic need; 0.57 mi fresh access; 6 nearby resources | K33: =IF($N33=0,"",IF(INDEX(Data!$I$2051:$I$2550,$N33)=0,"Add ID","Row "&(INDEX(Data!$I$2051:$I$2550,$N33)+7))) -> Row 257 | L33: =IF($N33=0,"",IF(INDEX(Data!$AN$2051:$AN$2550,$N33)=0,"",IF(INDEX(Data!$U$41:$U$540,INDEX(Data!$AN$2051:$AN$2550,$N33))="","",INDEX(Data!$U$41:$U$540,INDEX(Data!$AN$2051:$AN$2550,$N33))))) -> 215-400-7150 | N33: =IF(COUNTIFS(Data!$AR$2051:$AR$2550,21)=1,MATCH(21,Data!$AR$2051:$AR$2550,0),0) -> 201
A34: =IF($N34=0,"",22) -> 22 | B34: =IF($N34=0,"",INDEX(Data!$B$2051:$B$2550,$N34)) -> Ellwood School | C34: =IF($N34=0,"",INDEX(Data!$C$2051:$C$2550,$N34)) -> District | D34: =IF($N34=0,"",INDEX(Data!$G$2051:$G$2550,$N34)) -> 0.8007 | E34: =IF($N34=0,"",INDEX(Data!$F$2051:$F$2550,$N34)) -> 252 | F34: =IF($N34=0,"",INDEX(Data!$K$2051:$K$2550,$N34)) -> 0.5681186 | G34: =IF($N34=0,"",INDEX(Data!$L$2051:$L$2550,$N34)) -> 7 | H34: =IF($N34=0,"",INDEX(Data!$T$2051:$T$2550,$N34)) -> 42 | I34: =IF($N34=0,"",INDEX(Data!$U$2051:$U$2550,$N34)) -> Listed | J34: =IF($N34=0,"",INDEX(Data!$AA$2051:$AA$2550,$N34)) -> 80% economic need; 0.57 mi fresh access; 7 nearby resources | K34: =IF($N34=0,"",IF(INDEX(Data!$I$2051:$I$2550,$N34)=0,"Add ID","Row "&(INDEX(Data!$I$2051:$I$2550,$N34)+7))) -> Row 70 | L34: =IF($N34=0,"",IF(INDEX(Data!$AN$2051:$AN$2550,$N34)=0,"",IF(INDEX(Data!$U$41:$U$540,INDEX(Data!$AN$2051:$AN$2550,$N34))="","",INDEX(Data!$U$41:$U$540,INDEX(Data!$AN$2051:$AN$2550,$N34))))) -> 215-400-3540 | N34: =IF(COUNTIFS(Data!$AR$2051:$AR$2550,22)=1,MATCH(22,Data!$AR$2051:$AR$2550,0),0) -> 263
A35: =IF($N35=0,"",23) -> 23 | B35: =IF($N35=0,"",INDEX(Data!$B$2051:$B$2550,$N35)) -> William H. Loesche School | C35: =IF($N35=0,"",INDEX(Data!$C$2051:$C$2550,$N35)) -> District | D35: =IF($N35=0,"",INDEX(Data!$G$2051:$G$2550,$N35)) -> 0.7346 | E35: =IF($N35=0,"",INDEX(Data!$F$2051:$F$2550,$N35)) -> 1276 | F35: =IF($N35=0,"",INDEX(Data!$K$2051:$K$2550,$N35)) -> 0.45647318 | G35: =IF($N35=0,"",INDEX(Data!$L$2051:$L$2550,$N35)) -> 4 | H35: =IF($N35=0,"",INDEX(Data!$T$2051:$T$2550,$N35)) -> 40 | I35: =IF($N35=0,"",INDEX(Data!$U$2051:$U$2550,$N35)) -> Listed | J35: =IF($N35=0,"",INDEX(Data!$AA$2051:$AA$2550,$N35)) -> 73% economic need; 0.46 mi fresh access; 4 nearby resources | K35: =IF($N35=0,"",IF(INDEX(Data!$I$2051:$I$2550,$N35)=0,"Add ID","Row "&(INDEX(Data!$I$2051:$I$2550,$N35)+7))) -> Row 325 | L35: =IF($N35=0,"",IF(INDEX(Data!$AN$2051:$AN$2550,$N35)=0,"",IF(INDEX(Data!$U$41:$U$540,INDEX(Data!$AN$2051:$AN$2550,$N35))="","",INDEX(Data!$U$41:$U$540,INDEX(Data!$AN$2051:$AN$2550,$N35))))) -> 215-400-3020 | N35: =IF(COUNTIFS(Data!$AR$2051:$AR$2550,23)=1,MATCH(23,Data!$AR$2051:$AR$2550,0),0) -> 317
A36: =IF($N36=0,"",24) -> 24 | B36: =IF($N36=0,"",INDEX(Data!$B$2051:$B$2550,$N36)) -> Laura H. Carnell School | C36: =IF($N36=0,"",INDEX(Data!$C$2051:$C$2550,$N36)) -> District | D36: =IF($N36=0,"",INDEX(Data!$G$2051:$G$2550,$N36)) -> 0.7636 | E36: =IF($N36=0,"",INDEX(Data!$F$2051:$F$2550,$N36)) -> 652 | F36: =IF($N36=0,"",INDEX(Data!$K$2051:$K$2550,$N36)) -> 0.38637814 | G36: =IF($N36=0,"",INDEX(Data!$L$2051:$L$2550,$N36)) -> 4 | H36: =IF($N36=0,"",INDEX(Data!$T$2051:$T$2550,$N36)) -> 39 | I36: =IF($N36=0,"",INDEX(Data!$U$2051:$U$2550,$N36)) -> Listed | J36: =IF($N36=0,"",INDEX(Data!$AA$2051:$AA$2550,$N36)) -> 76% economic need; 0.39 mi fresh access; 4 nearby resources | K36: =IF($N36=0,"",IF(INDEX(Data!$I$2051:$I$2550,$N36)=0,"Add ID","Row "&(INDEX(Data!$I$2051:$I$2550,$N36)+7))) -> Row 175 | L36: =IF($N36=0,"",IF(INDEX(Data!$AN$2051:$AN$2550,$N36)=0,"",IF(INDEX(Data!$U$41:$U$540,INDEX(Data!$AN$2051:$AN$2550,$N36))="","",INDEX(Data!$U$41:$U$540,INDEX(Data!$AN$2051:$AN$2550,$N36))))) -> 215-400-3150 | N36: =IF(COUNTIFS(Data!$AR$2051:$AR$2550,24)=1,MATCH(24,Data!$AR$2051:$AR$2550,0),0) -> 262
A37: =IF($N37=0,"",25) -> 25 | B37: =IF($N37=0,"",INDEX(Data!$B$2051:$B$2550,$N37)) -> John H. Webster School | C37: =IF($N37=0,"",INDEX(Data!$C$2051:$C$2550,$N37)) -> District | D37: =IF($N37=0,"",INDEX(Data!$G$2051:$G$2550,$N37)) -> 0.8997 | E37: =IF($N37=0,"",INDEX(Data!$F$2051:$F$2550,$N37)) -> 413 | F37: =IF($N37=0,"",INDEX(Data!$K$2051:$K$2550,$N37)) -> 0.37561574 | G37: =IF($N37=0,"",INDEX(Data!$L$2051:$L$2550,$N37)) -> 7 | H37: =IF($N37=0,"",INDEX(Data!$T$2051:$T$2550,$N37)) -> 38 | I37: =IF($N37=0,"",INDEX(Data!$U$2051:$U$2550,$N37)) -> Listed | J37: =IF($N37=0,"",INDEX(Data!$AA$2051:$AA$2550,$N37)) -> 90% economic need; 0.38 mi fresh access; 7 nearby resources | K37: =IF($N37=0,"",IF(INDEX(Data!$I$2051:$I$2550,$N37)=0,"Add ID","Row "&(INDEX(Data!$I$2051:$I$2550,$N37)+7))) -> Row 147 | L37: =IF($N37=0,"",IF(INDEX(Data!$AN$2051:$AN$2550,$N37)=0,"",IF(INDEX(Data!$U$41:$U$540,INDEX(Data!$AN$2051:$AN$2550,$N37))="","",INDEX(Data!$U$41:$U$540,INDEX(Data!$AN$2051:$AN$2550,$N37))))) -> 215-400-7170 | N37: =IF(COUNTIFS(Data!$AR$2051:$AR$2550,25)=1,MATCH(25,Data!$AR$2051:$AR$2550,0),0) -> 216
A40: Missing-data queue
B41: =COUNTIFS(Data!$H$2051:$H$2550,"Yes",Data!$V$2051:$V$2550,"Missing data")&" schools have no complete score. Find them using School Search > Missing data." -> 12 schools have no complete score. Find them using School Search > Missing data.
A44: Weights | B44: Economic need | C44: Fresh access | D44: Resource gap | E44: Reach
A45: Active | B45: =IF($B$5="Baseline",B46,B47) -> 30 | C45: =IF($B$5="Baseline",C46,C47) -> 25 | D45: =IF($B$5="Baseline",D46,D47) -> 25 | E45: =IF($B$5="Baseline",E46,E47) -> 5
A46: Baseline | B46: 30 | C46: 25 | D46: 25 | E46: 5
...

Sheet School Search
A2: School search
A3: Search a name, ZIP or ID. Results update when you press Enter. Top 25 remains independent of these filters.
A4: Search name / ZIP / ID | D4: School type | G4: Results | J4: Page
D5: All | G5: Not marked served | J5: 1
A7: =SUM(Data!$Y$2051:$Y$2550)&" matches. Page "&J5&" of "&MAX(1,ROUNDUP(SUM(Data!$Y$2051:$Y$2550)/20,0)) -> 305 matches. Page 1 of 16
A8: Listed food access is provisional. Blank scores identify missing source data. Open School Profile for the evidence.
A10: Need rank | B10: School | C10: Type | D10: Economic % | E10: Enrollment | F10: Score /85 | G10: Already served | H10: Food evidence | I10: Status | J10: School ID | K10: Review row
A11: =IF($M11=0,"",IF(ISNUMBER(INDEX(Data!$X$2051:$X$2550,$M11)),INDEX(Data!$X$2051:$X$2550,$M11),"")) -> 1 | B11: =IF($M11=0,"",INDEX(Data!$B$2051:$B$2550,$M11)) -> Tacony Academy Charter School | C11: =IF($M11=0,"",INDEX(Data!$C$2051:$C$2550,$M11)) -> Charter | D11: =IF($M11=0,"",IF(ISNUMBER(INDEX(Data!$G$2051:$G$2550,$M11)),INDEX(Data!$G$2051:$G$2550,$M11),"")) -> 0.7204 | E11: =IF($M11=0,"",IF(ISNUMBER(INDEX(Data!$F$2051:$F$2550,$M11)),INDEX(Data!$F$2051:$F$2550,$M11),"")) -> 1090 | F11: =IF($M11=0,"",IF(ISNUMBER(INDEX(Data!$T$2051:$T$2550,$M11)),INDEX(Data!$T$2051:$T$2550,$M11),"")) -> 70 | G11: =IF($M11=0,"",INDEX(Data!$J$2051:$J$2550,$M11)) -> No | H11: =IF($M11=0,"",INDEX(Data!$U$2051:$U$2550,$M11)) -> Listed | I11: =IF($M11=0,"",INDEX(Data!$V$2051:$V$2550,$M11)) -> Candidate | J11: =IF($M11=0,"",INDEX(Data!$A$2051:$A$2550,$M11)) -> 3404 | K11: =IF($M11=0,"",IF(INDEX(Data!$I$2051:$I$2550,$M11)=0,"Add ID","Row "&(INDEX(Data!$I$2051:$I$2550,$M11)+7))) -> Row 287 | M11: =IF(COUNTIFS(Data!$Z$2051:$Z$2550,($J$5-1)*20+1)=1,MATCH(($J$5-1)*20+1,Data!$Z$2051:$Z$2550,0),0) -> 126
A12: =IF($M12=0,"",IF(ISNUMBER(INDEX(Data!$X$2051:$X$2550,$M12)),INDEX(Data!$X$2051:$X$2550,$M12),"")) -> 2 | B12: =IF($M12=0,"",INDEX(Data!$B$2051:$B$2550,$M12)) -> Joseph H. Brown School | C12: =IF($M12=0,"",INDEX(Data!$C$2051:$C$2550,$M12)) -> District | D12: =IF($M12=0,"",IF(ISNUMBER(INDEX(Data!$G$2051:$G$2550,$M12)),INDEX(Data!$G$2051:$G$2550,$M12),"")) -> 0.8056 | E12: =IF($M12=0,"",IF(ISNUMBER(INDEX(Data!$F$2051:$F$2550,$M12)),INDEX(Data!$F$2051:$F$2550,$M12),"")) -> 427 | F12: =IF($M12=0,"",IF(ISNUMBER(INDEX(Data!$T$2051:$T$2550,$M12)),INDEX(Data!$T$2051:$T$2550,$M12),"")) -> 68 | G12: =IF($M12=0,"",INDEX(Data!$J$2051:$J$2550,$M12)) -> No | H12: =IF($M12=0,"",INDEX(Data!$U$2051:$U$2550,$M12)) -> Listed | I12: =IF($M12=0,"",INDEX(Data!$V$2051:$V$2550,$M12)) -> Candidate | J12: =IF($M12=0,"",INDEX(Data!$A$2051:$A$2550,$M12)) -> 8210 | K12: =IF($M12=0,"",IF(INDEX(Data!$I$2051:$I$2550,$M12)=0,"Add ID","Row "&(INDEX(Data!$I$2051:$I$2550,$M12)+7))) -> Row 154 | M12: =IF(COUNTIFS(Data!$Z$2051:$Z$2550,($J$5-1)*20+2)=1,MATCH(($J$5-1)*20+2,Data!$Z$2051:$Z$2550,0),0) -> 299
A13: =IF($M13=0,"",IF(ISNUMBER(INDEX(Data!$X$2051:$X$2550,$M13)),INDEX(Data!$X$2051:$X$2550,$M13),"")) -> 3 | B13: =IF($M13=0,"",INDEX(Data!$B$2051:$B$2550,$M13)) -> New Foundations Charter School | C13: =IF($M13=0,"",INDEX(Data!$C$2051:$C$2550,$M13)) -> Charter | D13: =IF($M13=0,"",IF(ISNUMBER(INDEX(Data!$G$2051:$G$2550,$M13)),INDEX(Data!$G$2051:$G$2550,$M13),"")) -> 0.7084 | E13: =IF($M13=0,"",IF(ISNUMBER(INDEX(Data!$F$2051:$F$2550,$M13)),INDEX(Data!$F$2051:$F$2550,$M13),"")) -> 1538 | F13: =IF($M13=0,"",IF(ISNUMBER(INDEX(Data!$T$2051:$T$2550,$M13)),INDEX(Data!$T$2051:$T$2550,$M13),"")) -> 65 | G13: =IF($M13=0,"",INDEX(Data!$J$2051:$J$2550,$M13)) -> No | H13: =IF($M13=0,"",INDEX(Data!$U$2051:$U$2550,$M13)) -> Listed | I13: =IF($M13=0,"",INDEX(Data!$V$2051:$V$2550,$M13)) -> Candidate | J13: =IF($M13=0,"",INDEX(Data!$A$2051:$A$2550,$M13)) -> 3334 | K13: =IF($M13=0,"",IF(INDEX(Data!$I$2051:$I$2550,$M13)=0,"Add ID","Row "&(INDEX(Data!$I$2051:$I$2550,$M13)+7))) -> Row 211 | M13: =IF(COUNTIFS(Data!$Z$2051:$Z$2550,($J$5-1)*20+3)=1,MATCH(($J$5-1)*20+3,Data!$Z$2051:$Z$2550,0),0) -> 94
A14: =IF($M14=0,"",IF(ISNUMBER(INDEX(Data!$X$2051:$X$2550,$M14)),INDEX(Data!$X$2051:$X$2550,$M14),"")) -> 4 | B14: =IF($M14=0,"",INDEX(Data!$B$2051:$B$2550,$M14)) -> Southwest Leadership Academy Charter School | C14: =IF($M14=0,"",INDEX(Data!$C$2051:$C$2550,$M14)) -> Charter | D14: =IF($M14=0,"",IF(ISNUMBER(INDEX(Data!$G$2051:$G$2550,$M14)),INDEX(Data!$G$2051:$G$2550,$M14),"")) -> 1 | E14: =IF($M14=0,"",IF(ISNUMBER(INDEX(Data!$F$2051:$F$2550,$M14)),INDEX(Data!$F$2051:$F$2550,$M14),"")) -> 690 | F14: =IF($M14=0,"",IF(ISNUMBER(INDEX(Data!$T$2051:$T$2550,$M14)),INDEX(Data!$T$2051:$T$2550,$M14),"")) -> 64 | G14: =IF($M14=0,"",INDEX(Data!$J$2051:$J$2550,$M14)) -> No | H14: =IF($M14=0,"",INDEX(Data!$U$2051:$U$2550,$M14)) -> Listed | I14: =IF($M14=0,"",INDEX(Data!$V$2051:$V$2550,$M14)) -> Candidate | J14: =IF($M14=0,"",INDEX(Data!$A$2051:$A$2550,$M14)) -> 3392 | K14: =IF($M14=0,"",IF(INDEX(Data!$I$2051:$I$2550,$M14)=0,"Add ID","Row "&(INDEX(Data!$I$2051:$I$2550,$M14)+7))) -> Row 280 | M14: =IF(COUNTIFS(Data!$Z$2051:$Z$2550,($J$5-1)*20+4)=1,MATCH(($J$5-1)*20+4,Data!$Z$2051:$Z$2550,0),0) -> 120
A15: =IF($M15=0,"",IF(ISNUMBER(INDEX(Data!$X$2051:$X$2550,$M15)),INDEX(Data!$X$2051:$X$2550,$M15),"")) -> 4 | B15: =IF($M15=0,"",INDEX(Data!$B$2051:$B$2550,$M15)) -> Ad Prima Charter School | C15: =IF($M15=0,"",INDEX(Data!$C$2051:$C$2550,$M15)) -> Charter | D15: =IF($M15=0,"",IF(ISNUMBER(INDEX(Data!$G$2051:$G$2550,$M15)),INDEX(Data!$G$2051:$G$2550,$M15),"")) -> 0.9274 | E15: =IF($M15=0,"",IF(ISNUMBER(INDEX(Data!$F$2051:$F$2550,$M15)),INDEX(Data!$F$2051:$F$2550,$M15),"")) -> 617 | F15: =IF($M15=0,"",IF(ISNUMBER(INDEX(Data!$T$2051:$T$2550,$M15)),INDEX(Data!$T$2051:$T$2550,$M15),"")) -> 64 | G15: =IF($M15=0,"",INDEX(Data!$J$2051:$J$2550,$M15)) -> No | H15: =IF($M15=0,"",INDEX(Data!$U$2051:$U$2550,$M15)) -> Listed | I15: =IF($M15=0,"",INDEX(Data!$V$2051:$V$2550,$M15)) -> Candidate | J15: =IF($M15=0,"",INDEX(Data!$A$2051:$A$2550,$M15)) -> 3379 | K15: =IF($M15=0,"",IF(INDEX(Data!$I$2051:$I$2550,$M15)=0,"Add ID","Row "&(INDEX(Data!$I$2051:$I$2550,$M15)+7))) -> Row 15 | M15: =IF(COUNTIFS(Data!$Z$2051:$Z$2550,($J$5-1)*20+5)=1,MATCH(($J$5-1)*20+5,Data!$Z$2051:$Z$2550,0),0) -> 113
A16: =IF($M16=0,"",IF(ISNUMBER(INDEX(Data!$X$2051:$X$2550,$M16)),INDEX(Data!$X$2051:$X$2550,$M16),"")) -> 4 | B16: =IF($M16=0,"",INDEX(Data!$B$2051:$B$2550,$M16)) -> Rhawnhurst School | C16: =IF($M16=0,"",INDEX(Data!$C$2051:$C$2550,$M16)) -> District | D16: =IF($M16=0,"",IF(ISNUMBER(INDEX(Data!$G$2051:$G$2550,$M16)),INDEX(Data!$G$2051:$G$2550,$M16),"")) -> 0.7637 | E16: =IF($M16=0,"",IF(ISNUMBER(INDEX(Data!$F$2051:$F$2550,$M16)),INDEX(Data!$F$2051:$F$2550,$M16),"")) -> 584 | F16: =IF($M16=0,"",IF(ISNUMBER(INDEX(Data!$T$2051:$T$2550,$M16)),INDEX(Data!$T$2051:$T$2550,$M16),"")) -> 64 | G16: =IF($M16=0,"",INDEX(Data!$J$2051:$J$2550,$M16)) -> No | H16: =IF($M16=0,"",INDEX(Data!$U$2051:$U$2550,$M16)) -> Listed | I16: =IF($M16=0,"",INDEX(Data!$V$2051:$V$2550,$M16)) -> Candidate | J16: =IF($M16=0,"",INDEX(Data!$A$2051:$A$2550,$M16)) -> 8360 | K16: =IF($M16=0,"",IF(INDEX(Data!$I$2051:$I$2550,$M16)=0,"Add ID","Row "&(INDEX(Data!$I$2051:$I$2550,$M16)+7))) -> Row 254 | M16: =IF(COUNTIFS(Data!$Z$2051:$Z$2550,($J$5-1)*20+6)=1,MATCH(($J$5-1)*20+6,Data!$Z$2051:$Z$2550,0),0) -> 309
A17: =IF($M17=0,"",IF(ISNUMBER(INDEX(Data!$X$2051:$X$2550,$M17)),INDEX(Data!$X$2051:$X$2550,$M17),"")) -> 7 | B17: =IF($M17=0,"",INDEX(Data!$B$2051:$B$2550,$M17)) -> Penrose School | C17: =IF($M17=0,"",INDEX(Data!$C$2051:$C$2550,$M17)) -> District | D17: =IF($M17=0,"",IF(ISNUMBER(INDEX(Data!$G$2051:$G$2550,$M17)),INDEX(Data!$G$2051:$G$2550,$M17),"")) -> 0.8372 | E17: =IF($M17=0,"",IF(ISNUMBER(INDEX(Data!$F$2051:$F$2550,$M17)),INDEX(Data!$F$2051:$F$2550,$M17),"")) -> 429 | F17: =IF($M17=0,"",IF(ISNUMBER(INDEX(Data!$T$2051:$T$2550,$M17)),INDEX(Data!$T$2051:$T$2550,$M17),"")) -> 63 | G17: =IF($M17=0,"",INDEX(Data!$J$2051:$J$2550,$M17)) -> No | H17: =IF($M17=0,"",INDEX(Data!$U$2051:$U$2550,$M17)) -> Listed | I17: =IF($M17=0,"",INDEX(Data!$V$2051:$V$2550,$M17)) -> Candidate | J17: =IF($M17=0,"",INDEX(Data!$A$2051:$A$2550,$M17)) -> 1440 | K17: =IF($M17=0,"",IF(INDEX(Data!$I$2051:$I$2550,$M17)=0,"Add ID","Row "&(INDEX(Data!$I$2051:$I$2550,$M17)+7))) -> Row 236 | M17: =IF(COUNTIFS(Data!$Z$2051:$Z$2550,($J$5-1)*20+7)=1,MATCH(($J$5-1)*20+7,Data!$Z$2051:$Z$2550,0),0) -> 24
A18: =IF($M18=0,"",IF(ISNUMBER(INDEX(Data!$X$2051:$X$2550,$M18)),INDEX(Data!$X$2051:$X$2550,$M18),"")) -> 7 | B18: =IF($M18=0,"",INDEX(Data!$B$2051:$B$2550,$M18)) -> Robert E. Lamberton School | C18: =IF($M18=0,"",INDEX(Data!$C$2051:$C$2550,$M18)) -> District | D18: =IF($M18=0,"",IF(ISNUMBER(INDEX(Data!$G$2051:$G$2550,$M18)),INDEX(Data!$G$2051:$G$2550,$M18),"")) -> 0.8355 | E18: =IF($M18=0,"",IF(ISNUMBER(INDEX(Data!$F$2051:$F$2550,$M18)),INDEX(Data!$F$2051:$F$2550,$M18),"")) -> 362 | F18: =IF($M18=0,"",IF(ISNUMBER(INDEX(Data!$T$2051:$T$2550,$M18)),INDEX(Data!$T$2051:$T$2550,$M18),"")) -> 63 | G18: =IF($M18=0,"",INDEX(Data!$J$2051:$J$2550,$M18)) -> No | H18: =IF($M18=0,"",INDEX(Data!$U$2051:$U$2550,$M18)) -> Listed | I18: =IF($M18=0,"",INDEX(Data!$V$2051:$V$2550,$M18)) -> Candidate | J18: =IF($M18=0,"",INDEX(Data!$A$2051:$A$2550,$M18)) -> 4320 | K18: =IF($M18=0,"",IF(INDEX(Data!$I$2051:$I$2550,$M18)=0,"Add ID","Row "&(INDEX(Data!$I$2051:$I$2550,$M18)+7))) -> Row 259 | M18: =IF(COUNTIFS(Data!$Z$2051:$Z$2550,($J$5-1)*20+8)=1,MATCH(($J$5-1)*20+8,Data!$Z$2051:$Z$2550,0),0) -> 166
A19: =IF($M19=0,"",IF(ISNUMBER(INDEX(Data!$X$2051:$X$2550,$M19)),INDEX(Data!$X$2051:$X$2550,$M19),"")) -> 9 | B19: =IF($M19=0,"",INDEX(Data!$B$2051:$B$2550,$M19)) -> Lankenau High School | C19: =IF($M19=0,"",INDEX(Data!$C$2051:$C$2550,$M19)) -> District | D19: =IF($M19=0,"",IF(ISNUMBER(INDEX(Data!$G$2051:$G$2550,$M19)),INDEX(Data!$G$2051:$G$2550,$M19),"")) -> 0.64 | E19: =IF($M19=0,"",IF(ISNUMBER(INDEX(Data!$F$2051:$F$2550,$M19)),INDEX(Data!$F$2051:$F$2550,$M19),"")) -> 225 | F19: =IF($M19=0,"",IF(ISNUMBER(INDEX(Data!$T$2051:$T$2550,$M19)),INDEX(Data!$T$2051:$T$2550,$M19),"")) -> 62 | G19: =IF($M19=0,"",INDEX(Data!$J$2051:$J$2550,$M19)) -> No | H19: =IF($M19=0,"",INDEX(Data!$U$2051:$U$2550,$M19)) -> Listed | I19: =IF($M19=0,"",INDEX(Data!$V$2051:$V$2550,$M19)) -> Candidate | J19: =IF($M19=0,"",INDEX(Data!$A$2051:$A$2550,$M19)) -> 6540 | K19: =IF($M19=0,"",IF(INDEX(Data!$I$2051:$I$2550,$M19)=0,"Add ID","Row "&(INDEX(Data!$I$2051:$I$2550,$M19)+7))) -> Row 174 | M19: =IF(COUNTIFS(Data!$Z$2051:$Z$2550,($J$5-1)*20+9)=1,MATCH(($J$5-1)*20+9,Data!$Z$2051:$Z$2550,0),0) -> 251
A20: =IF($M20=0,"",IF(ISNUMBER(INDEX(Data!$X$2051:$X$2550,$M20)),INDEX(Data!$X$2051:$X$2550,$M20),"")) -> 10 | B20: =IF($M20=0,"",INDEX(Data!$B$2051:$B$2550,$M20)) -> Robert B. Pollock School | C20: =IF($M20=0,"",INDEX(Data!$C$2051:$C$2550,$M20)) -> District | D20: =IF($M20=0,"",IF(ISNUMBER(INDEX(Data!$G$2051:$G$2550,$M20)),INDEX(Data!$G$2051:$G$2550,$M20),"")) -> 0.7341 | E20: =IF($M20=0,"",IF(ISNUMBER(INDEX(Data!$F$2051:$F$2550,$M20)),INDEX(Data!$F$2051:$F$2550,$M20),"")) -> 900 | F20: =IF($M20=0,"",IF(ISNUMBER(INDEX(Data!$T$2051:$T$2550,$M20)),INDEX(Data!$T$2051:$T$2550,$M20),"")) -> 60 | G20: =IF($M20=0,"",INDEX(Data!$J$2051:$J$2550,$M20)) -> No | H20: =IF($M20=0,"",INDEX(Data!$U$2051:$U$2550,$M20)) -> Listed | I20: =IF($M20=0,"",INDEX(Data!$V$2051:$V$2550,$M20)) -> Candidate | J20: =IF($M20=0,"",INDEX(Data!$A$2051:$A$2550,$M20)) -> 8410 | K20: =IF($M20=0,"",IF(INDEX(Data!$I$2051:$I$2550,$M20)=0,"Add ID","Row "&(INDEX(Data!$I$2051:$I$2550,$M20)+7))) -> Row 258 | M20: =IF(COUNTIFS(Data!$Z$2051:$Z$2550,($J$5-1)*20+10)=1,MATCH(($J$5-1)*20+10,Data!$Z$2051:$Z$2550,0),0) -> 314
A21: =IF($M21=0,"",IF(ISNUMBER(INDEX(Data!$X$2051:$X$2550,$M21)),INDEX(Data!$X$2051:$X$2550,$M21),"")) -> 10 | B21: =IF($M21=0,"",INDEX(Data!$B$2051:$B$2550,$M21)) -> Northeast High School | C21: =IF($M21=0,"",INDEX(Data!$C$2051:$C$2550,$M21)) -> District | D21: =IF($M21=0,"",IF(ISNUMBER(INDEX(Data!$G$2051:$G$2550,$M21)),INDEX(Data!$G$2051:$G$2550,$M21),"")) -> 0.7192 | E21: =IF($M21=0,"",IF(ISNUMBER(INDEX(Data!$F$2051:$F$2550,$M21)),INDEX(Data!$F$2051:$F$2550,$M21),"")) -> 3541 | F21: =IF($M21=0,"",IF(ISNUMBER(INDEX(Data!$T$2051:$T$2550,$M21)),INDEX(Data!$T$2051:$T$2550,$M21),"")) -> 60 | G21: =IF($M21=0,"",INDEX(Data!$J$2051:$J$2550,$M21)) -> No | H21: =IF($M21=0,"",INDEX(Data!$U$2051:$U$2550,$M21)) -> Listed | I21: =IF($M21=0,"",INDEX(Data!$V$2051:$V$2550,$M21)) -> Candidate | J21: =IF($M21=0,"",INDEX(Data!$A$2051:$A$2550,$M21)) -> 8020 | K21: =IF($M21=0,"",IF(INDEX(Data!$I$2051:$I$2550,$M21)=0,"Add ID","Row "&(INDEX(Data!$I$2051:$I$2550,$M21)+7))) -> Row 213 | M21: =IF(COUNTIFS(Data!$Z$2051:$Z$2550,($J$5-1)*20+11)=1,MATCH(($J$5-1)*20+11,Data!$Z$2051:$Z$2550,0),0) -> 287
A22: =IF($M22=0,"",IF(ISNUMBER(INDEX(Data!$X$2051:$X$2550,$M22)),INDEX(Data!$X$2051:$X$2550,$M22),"")) -> 10 | B22: =IF($M22=0,"",INDEX(Data!$B$2051:$B$2550,$M22)) -> Aloysius L. Fitzpatrick School | C22: =IF($M22=0,"",INDEX(Data!$C$2051:$C$2550,$M22)) -> District | D22: =IF($M22=0,"",IF(ISNUMBER(INDEX(Data!$G$2051:$G$2550,$M22)),INDEX(Data!$G$2051:$G$2550,$M22),"")) -> 0.7176 | E22: =IF($M22=0,"",IF(ISNUMBER(INDEX(Data!$F$2051:$F$2550,$M22)),INDEX(Data!$F$2051:$F$2550,$M22),"")) -> 868 | F22: =IF($M22=0,"",IF(ISNUMBER(INDEX(Data!$T$2051:$T$2550,$M22)),INDEX(Data!$T$2051:$T$2550,$M22),"")) -> 60 | G22: =IF($M22=0,"",INDEX(Data!$J$2051:$J$2550,$M22)) -> No | H22: =IF($M22=0,"",INDEX(Data!$U$2051:$U$2550,$M22)) -> Listed | I22: =IF($M22=0,"",INDEX(Data!$V$2051:$V$2550,$M22)) -> Candidate | J22: =IF($M22=0,"",INDEX(Data!$A$2051:$A$2550,$M22)) -> 8390 | K22: =IF($M22=0,"",IF(INDEX(Data!$I$2051:$I$2550,$M22)=0,"Add ID","Row "&(INDEX(Data!$I$2051:$I$2550,$M22)+7))) -> Row 23 | M22: =IF(COUNTIFS(Data!$Z$2051:$Z$2550,($J$5-1)*20+12)=1,MATCH(($J$5-1)*20+12,Data!$Z$2051:$Z$2550,0),0) -> 312
A23: =IF($M23=0,"",IF(ISNUMBER(INDEX(Data!$X$2051:$X$2550,$M23)),INDEX(Data!$X$2051:$X$2550,$M23),"")) -> 10 | B23: =IF($M23=0,"",INDEX(Data!$B$2051:$B$2550,$M23)) -> Franklin Towne Charter Elementary School | C23: =IF($M23=0,"",INDEX(Data!$C$2051:$C$2550,$M23)) -> Charter | D23: =IF($M23=0,"",IF(ISNUMBER(INDEX(Data!$G$2051:$G$2550,$M23)),INDEX(Data!$G$2051:$G$2550,$M23),"")) -> 0.6767 | E23: =IF($M23=0,"",IF(ISNUMBER(INDEX(Data!$F$2051:$F$2550,$M23)),INDEX(Data!$F$2051:$F$2550,$M23),"")) -> 958 | F23: =IF($M23=0,"",IF(ISNUMBER(INDEX(Data!$T$2051:$T$2550,$M23)),INDEX(Data!$T$2051:$T$2550,$M23),"")) -> 60 | G23: =IF($M23=0,"",INDEX(Data!$J$2051:$J$2550,$M23)) -> No | H23: =IF($M23=0,"",INDEX(Data!$U$2051:$U$2550,$M23)) -> Listed | I23: =IF($M23=0,"",INDEX(Data!$V$2051:$V$2550,$M23)) -> Candidate | J23: =IF($M23=0,"",INDEX(Data!$A$2051:$A$2550,$M23)) -> 3403 | K23: =IF($M23=0,"",IF(INDEX(Data!$I$2051:$I$2550,$M23)=0,"Add ID","Row "&(INDEX(Data!$I$2051:$I$2550,$M23)+7))) -> Row 92 | M23: =IF(COUNTIFS(Data!$Z$2051:$Z$2550,($J$5-1)*20+13)=1,MATCH(($J$5-1)*20+13,Data!$Z$2051:$Z$2550,0),0) -> 125
A24: =IF($M24=0,"",IF(ISNUMBER(INDEX(Data!$X$2051:$X$2550,$M24)),INDEX(Data!$X$2051:$X$2550,$M24),"")) -> 10 | B24: =IF($M24=0,"",INDEX(Data!$B$2051:$B$2550,$M24)) -> Charles C.A. Baldi Middle School | C24: =IF($M24=0,"",INDEX(Data!$C$2051:$C$2550,$M24)) -> District | D24: =IF($M24=0,"",IF(ISNUMBER(INDEX(Data!$G$2051:$G$2550,$M24)),INDEX(Data!$G$2051:$G$2550,$M24),"")) -> 0.6683 | E24: =IF($M24=0,"",IF(ISNUMBER(INDEX(Data!$F$2051:$F$2550,$M24)),INDEX(Data!$F$2051:$F$2550,$M24),"")) -> 1424 | F24: =IF($M24=0,"",IF(ISNUMBER(INDEX(Data!$T$2051:$T$2550,$M24)),INDEX(Data!$T$2051:$T$2550,$M24),"")) -> 60 | G24: =IF($M24=0,"",INDEX(Data!$J$2051:$J$2550,$M24)) -> No | H24: =IF($M24=0,"",INDEX(Data!$U$2051:$U$2550,$M24)) -> Listed | I24: =IF($M24=0,"",INDEX(Data!$V$2051:$V$2550,$M24)) -> Candidate | J24: =IF($M24=0,"",INDEX(Data!$A$2051:$A$2550,$M24)) -> 8160 | K24: =IF($M24=0,"",IF(INDEX(Data!$I$2051:$I$2550,$M24)=0,"Add ID","Row "&(INDEX(Data!$I$2051:$I$2550,$M24)+7))) -> Row 47 | M24: =IF(COUNTIFS(Data!$Z$2051:$Z$2550,($J$5-1)*20+14)=1,MATCH(($J$5-1)*20+14,Data!$Z$2051:$Z$2550,0),0) -> 296
A25: =IF($M25=0,"",IF(ISNUMBER(INDEX(Data!$X$2051:$X$2550,$M25)),INDEX(Data!$X$2051:$X$2550,$M25),"")) -> 10 | B25: =IF($M25=0,"",INDEX(Data!$B$2051:$B$2550,$M25)) -> Joseph Greenberg School | C25: =IF($M25=0,"",INDEX(Data!$C$2051:$C$2550,$M25)) -> District | D25: =IF($M25=0,"",IF(ISNUMBER(INDEX(Data!$G$2051:$G$2550,$M25)),INDEX(Data!$G$2051:$G$2550,$M25),"")) -> 0.5234 | E25: =IF($M25=0,"",IF(ISNUMBER(INDEX(Data!$F$2051:$F$2550,$M25)),INDEX(Data!$F$2051:$F$2550,$M25),"")) -> 1048 | F25: =IF($M25=0,"",IF(ISNUMBER(INDEX(Data!$T$2051:$T$2550,$M25)),INDEX(Data!$T$2051:$T$2550,$M25),"")) -> 60 | G25: =IF($M25=0,"",INDEX(Data!$J$2051:$J$2550,$M25)) -> No | H25: =IF($M25=0,"",INDEX(Data!$U$2051:$U$2550,$M25)) -> Listed | I25: =IF($M25=0,"",INDEX(Data!$V$2051:$V$2550,$M25)) -> Candidate | J25: =IF($M25=0,"",INDEX(Data!$A$2051:$A$2550,$M25)) -> 8430 | K25: =IF($M25=0,"",IF(INDEX(Data!$I$2051:$I$2550,$M25)=0,"Add ID","Row "&(INDEX(Data!$I$2051:$I$2550,$M25)+7))) -> Row 153 | M25: =IF(COUNTIFS(Data!$Z$2051:$Z$2550,($J$5-1)*20+15)=1,MATCH(($J$5-1)*20+15,Data!$Z$2051:$Z$2550,0),0) -> 316
A26: =IF($M26=0,"",IF(ISNUMBER(INDEX(Data!$X$2051:$X$2550,$M26)),INDEX(Data!$X$2051:$X$2550,$M26),"")) -> 16 | B26: =IF($M26=0,"",INDEX(Data!$B$2051:$B$2550,$M26)) -> Bridesburg School | C26: =IF($M26=0,"",INDEX(Data!$C$2051:$C$2550,$M26)) -> District | D26: =IF($M26=0,"",IF(ISNUMBER(INDEX(Data!$G$2051:$G$2550,$M26)),INDEX(Data!$G$2051:$G$2550,$M26),"")) -> 0.6934 | E26: =IF($M26=0,"",IF(ISNUMBER(INDEX(Data!$F$2051:$F$2550,$M26)),INDEX(Data!$F$2051:$F$2550,$M26),"")) -> 522 | F26: =IF($M26=0,"",IF(ISNUMBER(INDEX(Data!$T$2051:$T$2550,$M26)),INDEX(Data!$T$2051:$T$2550,$M26),"")) -> 59 | G26: =IF($M26=0,"",INDEX(Data!$J$2051:$J$2550,$M26)) -> No | H26: =IF($M26=0,"",INDEX(Data!$U$2051:$U$2550,$M26)) -> Listed | I26: =IF($M26=0,"",INDEX(Data!$V$2051:$V$2550,$M26)) -> Candidate | J26: =IF($M26=0,"",INDEX(Data!$A$2051:$A$2550,$M26)) -> 7470 | K26: =IF($M26=0,"",IF(INDEX(Data!$I$2051:$I$2550,$M26)=0,"Add ID","Row "&(INDEX(Data!$I$2051:$I$2550,$M26)+7))) -> Row 41 | M26: =IF(COUNTIFS(Data!$Z$2051:$Z$2550,($J$5-1)*20+16)=1,MATCH(($J$5-1)*20+16,Data!$Z$2051:$Z$2550,0),0) -> 280
A27: =IF($M27=0,"",IF(ISNUMBER(INDEX(Data!$X$2051:$X$2550,$M27)),INDEX(Data!$X$2051:$X$2550,$M27),"")) -> 17 | B27: =IF($M27=0,"",INDEX(Data!$B$2051:$B$2550,$M27)) -> Kensington High School | C27: =IF($M27=0,"",INDEX(Data!$C$2051:$C$2550,$M27)) -> District | D27: =IF($M27=0,"",IF(ISNUMBER(INDEX(Data!$G$2051:$G$2550,$M27)),INDEX(Data!$G$2051:$G$2550,$M27),"")) -> 0.8519 | E27: =IF($M27=0,"",IF(ISNUMBER(INDEX(Data!$F$2051:$F$2550,$M27)),INDEX(Data!$F$2051:$F$2550,$M27),"")) -> 447 | F27: =IF($M27=0,"",IF(ISNUMBER(INDEX(Data!$T$2051:$T$2550,$M27)),INDEX(Data!$T$2051:$T$2550,$M27),"")) -> 58 | G27: =IF($M27=0,"",INDEX(Data!$J$2051:$J$2550,$M27)) -> No | H27: =IF($M27=0,"",INDEX(Data!$U$2051:$U$2550,$M27)) -> Listed | I27: =IF($M27=0,"",INDEX(Data!$V$2051:$V$2550,$M27)) -> Candidate | J27: =IF($M27=0,"",INDEX(Data!$A$2051:$A$2550,$M27)) -> 5700 | K27: =IF($M27=0,"",IF(INDEX(Data!$I$2051:$I$2550,$M27)=0,"Add ID","Row "&(INDEX(Data!$I$2051:$I$2550,$M27)+7))) -> Row 165 | M27: =IF(COUNTIFS(Data!$Z$2051:$Z$2550,($J$5-1)*20+17)=1,MATCH(($J$5-1)*20+17,Data!$Z$2051:$Z$2550,0),0) -> 221
A28: =IF($M28=0,"",IF(ISNUMBER(INDEX(Data!$X$2051:$X$2550,$M28)),INDEX(Data!$X$2051:$X$2550,$M28),"")) -> 17 | B28: =IF($M28=0,"",INDEX(Data!$B$2051:$B$2550,$M28)) -> Walter B. Saul High School | C28: =IF($M28=0,"",INDEX(Data!$C$2051:$C$2550,$M28)) -> District | D28: =IF($M28=0,"",IF(ISNUMBER(INDEX(Data!$G$2051:$G$2550,$M28)),INDEX(Data!$G$2051:$G$2550,$M28),"")) -> 0.674 | E28: =IF($M28=0,"",IF(ISNUMBER(INDEX(Data!$F$2051:$F$2550,$M28)),INDEX(Data!$F$2051:$F$2550,$M28),"")) -> 406 | F28: =IF($M28=0,"",IF(ISNUMBER(INDEX(Data!$T$2051:$T$2550,$M28)),INDEX(Data!$T$2051:$T$2550,$M28),"")) -> 58 | G28: =IF($M28=0,"",INDEX(Data!$J$2051:$J$2550,$M28)) -> No | H28: =IF($M28=0,"",INDEX(Data!$U$2051:$U$2550,$M28)) -> Listed | I28: =IF($M28=0,"",INDEX(Data!$V$2051:$V$2550,$M28)) -> Candidate | J28: =IF($M28=0,"",INDEX(Data!$A$2051:$A$2550,$M28)) -> 6040 | K28: =IF($M28=0,"",IF(INDEX(Data!$I$2051:$I$2550,$M28)=0,"Add ID","Row "&(INDEX(Data!$I$2051:$I$2550,$M28)+7))) -> Row 312 | M28: =IF(COUNTIFS(Data!$Z$2051:$Z$2550,($J$5-1)*20+18)=1,MATCH(($J$5-1)*20+18,Data!$Z$2051:$Z$2550,0),0) -> 225
A29: =IF($M29=0,"",IF(ISNUMBER(INDEX(Data!$X$2051:$X$2550,$M29)),INDEX(Data!$X$2051:$X$2550,$M29),"")) -> 17 | B29: =IF($M29=0,"",INDEX(Data!$B$2051:$B$2550,$M29)) -> Shawmont School | C29: =IF($M29=0,"",INDEX(Data!$C$2051:$C$2550,$M29)) -> District | D29: =IF($M29=0,"",IF(ISNUMBER(INDEX(Data!$G$2051:$G$2550,$M29)),INDEX(Data!$G$2051:$G$2550,$M29),"")) -> 0.6284 | E29: =IF($M29=0,"",IF(ISNUMBER(INDEX(Data!$F$2051:$F$2550,$M29)),INDEX(Data!$F$2051:$F$2550,$M29),"")) -> 457 | F29: =IF($M29=0,"",IF(ISNUMBER(INDEX(Data!$T$2051:$T$2550,$M29)),INDEX(Data!$T$2051:$T$2550,$M29),"")) -> 58 | G29: =IF($M29=0,"",INDEX(Data!$J$2051:$J$2550,$M29)) -> No | H29: =IF($M29=0,"",INDEX(Data!$U$2051:$U$2550,$M29)) -> Listed | I29: =IF($M29=0,"",INDEX(Data!$V$2051:$V$2550,$M29)) -> Candidate | J29: =IF($M29=0,"",INDEX(Data!$A$2051:$A$2550,$M29)) -> 6380 | K29: =IF($M29=0,"",IF(INDEX(Data!$I$2051:$I$2550,$M29)=0,"Add ID","Row "&(INDEX(Data!$I$2051:$I$2550,$M29)+7))) -> Row 275 | M29: =IF(COUNTIFS(Data!$Z$2051:$Z$2550,($J$5-1)*20+19)=1,MATCH(($J$5-1)*20+19,Data!$Z$2051:$Z$2550,0),0) -> 242
A30: =IF($M30=0,"",IF(ISNUMBER(INDEX(Data!$X$2051:$X$2550,$M30)),INDEX(Data!$X$2051:$X$2550,$M30),"")) -> 20 | B30: =IF($M30=0,"",INDEX(Data!$B$2051:$B$2550,$M30)) -> John F. McCloskey School | C30: =IF($M30=0,"",INDEX(Data!$C$2051:$C$2550,$M30)) -> District | D30: =IF($M30=0,"",IF(ISNUMBER(INDEX(Data!$G$2051:$G$2550,$M30)),INDEX(Data!$G$2051:$G$2550,$M30),"")) -> 0.7557 | E30: =IF($M30=0,"",IF(ISNUMBER(INDEX(Data!$F$2051:$F$2550,$M30)),INDEX(Data!$F$2051:$F$2550,$M30),"")) -> 217 | F30: =IF($M30=0,"",IF(ISNUMBER(INDEX(Data!$T$2051:$T$2550,$M30)),INDEX(Data!$T$2051:$T$2550,$M30),"")) -> 57 | G30: =IF($M30=0,"",INDEX(Data!$J$2051:$J$2550,$M30)) -> No | H30: =IF($M30=0,"",INDEX(Data!$U$2051:$U$2550,$M30)) -> Listed | I30: =IF($M30=0,"",INDEX(Data!$V$2051:$V$2550,$M30)) -> Candidate | J30: =IF($M30=0,"",INDEX(Data!$A$2051:$A$2550,$M30)) -> 6310 | K30: =IF($M30=0,"",IF(INDEX(Data!$I$2051:$I$2550,$M30)=0,"Add ID","Row "&(INDEX(Data!$I$2051:$I$2550,$M30)+7))) -> Row 145 | M30: =IF(COUNTIFS(Data!$Z$2051:$Z$2550,($J$5-1)*20+20)=1,MATCH(($J$5-1)*20+20,Data!$Z$2051:$Z$2550,0),0) -> 237

Sheet School Profile
A2: School profile
A3: Choose a school to see its need, evidence and next action. | K3: =IF(COUNTIFS(Data!$B$2051:$B$2550,B5)=1,MATCH(B5,Data!$B$2051:$B$2550,0),0) -> 1
A4: School | K4: =IF($K$3=0,"",INDEX(Data!$AF$2051:$AF$2550,$K$3)) -> 39.921497
B5: John Bartram High School | K5: =IF($K$3=0,"",INDEX(Data!$AG$2051:$AG$2550,$K$3)) -> -75.234056
K7: =IF($K$3=0,0,INDEX(Data!$AN$2051:$AN$2550,$K$3)) -> 1
A8: School ID | B8: =IF($K$3=0,"",INDEX(Data!$A$2051:$A$2550,$K$3)) -> 1010 | D8: Rubric component | E8: Points
A9: School type | B9: =IF($K$3=0,"",INDEX(Data!$C$2051:$C$2550,$K$3)) -> District | D9: Economic need | E9: =IF($K$3=0,"",IF(ISNUMBER(INDEX(Data!$O$2051:$O$2550,$K$3)),INDEX(Data!$O$2051:$O$2550,$K$3),"")) -> 25
A10: School address | B10: =IF($K$3=0,"",INDEX(Data!$AE$2051:$AE$2550,$K$3)) -> 2401 S 67TH ST | D10: Fresh access | E10: =IF($K$3=0,"",IF(ISNUMBER(INDEX(Data!$P$2051:$P$2550,$K$3)),INDEX(Data!$P$2051:$P$2550,$K$3),"")) -> 10
A11: Economic disadvantage | B11: =IF($K$3=0,"",IF(ISNUMBER(INDEX(Data!$G$2051:$G$2550,$K$3)),INDEX(Data!$G$2051:$G$2550,$K$3),"")) -> 0.8053 | D11: Resource gap | E11: =IF($K$3=0,"",IF(ISNUMBER(INDEX(Data!$Q$2051:$Q$2550,$K$3)),INDEX(Data!$Q$2051:$Q$2550,$K$3),"")) -> 5
A12: Enrollment | B12: =IF($K$3=0,"",IF(ISNUMBER(INDEX(Data!$F$2051:$F$2550,$K$3)),INDEX(Data!$F$2051:$F$2550,$K$3),"")) -> 594 | D12: Reach | E12: =IF($K$3=0,"",IF(ISNUMBER(INDEX(Data!$R$2051:$R$2550,$K$3)),INDEX(Data!$R$2051:$R$2550,$K$3),"")) -> 4
A13: Active priority score /85 | B13: =IF($K$3=0,"",IF(ISNUMBER(INDEX(Data!$T$2051:$T$2550,$K$3)),INDEX(Data!$T$2051:$T$2550,$K$3),"")) -> 44
A14: Baseline score /85 | B14: =IF($K$3=0,"",IF(ISNUMBER(INDEX(Data!$S$2051:$S$2550,$K$3)),INDEX(Data!$S$2051:$S$2550,$K$3),"")) -> 44
A15: Food evidence | B15: =IF($K$3=0,"",INDEX(Data!$U$2051:$U$2550,$K$3)) -> Listed | D15: =IF($K$3=0,"",IF(INDEX(Data!$I$2051:$I$2550,$K$3)=0,"Add the school ID to Staff Review","Update Staff Review row "&(INDEX(Data!$I$2051:$I$2550,$K$3)+7))) -> Update Staff Review row 143
A16: Already served (staff flag) | B16: =IF($K$3=0,"",INDEX(Data!$J$2051:$J$2550,$K$3)) -> No
A17: Outreach status | B17: =IF($K$3=0,"",INDEX(Data!$AH$2051:$AH$2550,$K$3)) -> Not contacted | D17: =IF($K$3=0,"",IF(INDEX(Data!$C$2051:$C$2550,$K$3)="Charter","Confirm current Title I eligibility. Published status used: 2025–26.","District-operated public school.")) -> District-operated public school.
A18: Scope / target status | B18: =IF($K$3=0,"",INDEX(Data!$V$2051:$V$2550,$K$3)) -> Candidate
A20: Fresh access miles | B20: =IF($K$3=0,"",IF(ISNUMBER(INDEX(Data!$K$2051:$K$2550,$K$3)),INDEX(Data!$K$2051:$K$2550,$K$3),"")) -> 0.33978194 | D20: Listed miles do not establish produce quality, affordability or walking access.
A21: Fresh access basis | B21: =IF($K$3=0,"",INDEX(Data!$M$2051:$M$2550,$K$3)) -> Listed
A22: Nearby resources ≤1mi | B22: =IF($K$3=0,"",IF(ISNUMBER(INDEX(Data!$L$2051:$L$2550,$K$3)),INDEX(Data!$L$2051:$L$2550,$K$3),"")) -> 4 | D22: Verified inputs require a date and evidence in Staff Review.
A23: Resource basis | B23: =IF($K$3=0,"",INDEX(Data!$N$2051:$N$2550,$K$3)) -> Listed
A26: Nearest listed supermarket | B26: =IF($K$3=0,"",INDEX(Data!$AC$2051:$AC$2550,$K$3)) -> Cousin's Fresh Market Inc
A27: Retailer address | B27: =IF($K$3=0,"",INDEX(Data!$AD$2051:$AD$2550,$K$3)) -> 6411 Woodland Ave, Philadelphia, PA, 19142
A30: Nearby listed food sites
A31: Active City Food Site candidates within one mile. Check hours, recurrence and eligibility before counting as verified access.
A33: Miles | B33: Food site | C33: Address | E33: Website
A34: =IF($K34=0,"",INDEX(Data!$M$511:$M$1010,$K34)) -> 0.19201505 | B34: =IF($K$3=0,"",IF($K34=0,"No listed candidate within 1 mile",INDEX(Data!$B$511:$B$1010,$K34))) -> Revelation Philadelphia Ministry Inc | C34: =IF($K34=0,"",INDEX(Data!$C$511:$C$1010,$K34)) -> 2561 South 67th St | E34: =IF($K34=0,"",INDEX(Data!$L$511:$L$1010,$K34)) -> https://www.sharefoodprogram.org/ | K34: =IF(COUNTIFS(Data!$N$511:$N$1010,1)=1,MATCH(1,Data!$N$511:$N$1010,0),0) -> 190
A35: =IF($K35=0,"",INDEX(Data!$M$511:$M$1010,$K35)) -> 0.4216979 | B35: =IF($K35=0,"",INDEX(Data!$B$511:$B$1010,$K35)) -> Catholic Social Services Southwest Family Service Center | C35: =IF($K35=0,"",INDEX(Data!$C$511:$C$1010,$K35)) -> 6214 Grays Ave | E35: =IF($K35=0,"",INDEX(Data!$L$511:$L$1010,$K35)) -> https://nutritionaldevelopmentservices.org/ | K35: =IF(COUNTIFS(Data!$N$511:$N$1010,2)=1,MATCH(2,Data!$N$511:$N$1010,0),0) -> 245
A36: =IF($K36=0,"",INDEX(Data!$M$511:$M$1010,$K36)) -> 0.5395979 | B36: =IF($K36=0,"",INDEX(Data!$B$511:$B$1010,$K36)) -> Resurrection Community Church | C36: =IF($K36=0,"",INDEX(Data!$C$511:$C$1010,$K36)) -> 6200 Dicks Ave | E36: =IF($K36=0,"",INDEX(Data!$L$511:$L$1010,$K36)) -> https://www.sharefoodprogram.org/ | K36: =IF(COUNTIFS(Data!$N$511:$N$1010,3)=1,MATCH(3,Data!$N$511:$N$1010,0),0) -> 244
A37: =IF($K37=0,"",INDEX(Data!$M$511:$M$1010,$K37)) -> 0.92788676 | B37: =IF($K37=0,"",INDEX(Data!$B$511:$B$1010,$K37)) -> Ezekiel Baptist Church | C37: =IF($K37=0,"",INDEX(Data!$C$511:$C$1010,$K37)) -> 5701 Grays Ave | E37: =IF($K37=0,"",INDEX(Data!$L$511:$L$1010,$K37)) -> https://www.philabundance.org/ | K37: =IF(COUNTIFS(Data!$N$511:$N$1010,4)=1,MATCH(4,Data!$N$511:$N$1010,0),0) -> 217
A38: =IF($K38=0,"",INDEX(Data!$M$511:$M$1010,$K38)) | B38: =IF($K38=0,"",INDEX(Data!$B$511:$B$1010,$K38)) | C38: =IF($K38=0,"",INDEX(Data!$C$511:$C$1010,$K38)) | E38: =IF($K38=0,"",INDEX(Data!$L$511:$L$1010,$K38)) | K38: =IF(COUNTIFS(Data!$N$511:$N$1010,5)=1,MATCH(5,Data!$N$511:$N$1010,0),0) -> 0
A40: School phone | B40: =IF($K$7=0,"",IF(LEN(INDEX(Data!$U$41:$U$540,$K$7))=0,"Not published",INDEX(Data!$U$41:$U$540,$K$7))) -> 215-400-8100
A41: School website | B41: =IF($K$7=0,"",INDEX(Data!$V$41:$V$540,$K$7)) -> https://bartram.philasd.org/

Sheet Staff Review
A2: Staff review and service list
A3: Filter School name. Set Already served to Yes to remove a school from targets; No means unchecked. Amber cells are editable.
A5: Food evidence is optional for initial targeting. Enter a verified value, date and evidence to replace a listed estimate.
A7: School ID | B7: School name | C7: Already served | D7: Verified fresh miles | E7: Fresh checked | F7: Verified resources ≤1mi | G7: Resources checked | H7: Evidence / notes | I7: Owner | J7: Contact stage | K7: Readiness | L7: Record status
A8: 6090 | B8: =IF(A8="","",IF(COUNTIFS(Data!$A$2:$A$501,A8)=1,INDEX(Data!$B$2:$B$501,MATCH(A8,Data!$A$2:$A$501,0)),"Not in current directory")) -> A. Philip Randolph Career and Technical High School | C8: No | J8: Not contacted | K8: Unknown | L8: =IF(A8="","",IF(COUNTIFS($A$8:$A$507,A8)<>1,"Duplicate ID",IF(COUNTIFS(Data!$A$2:$A$501,A8)<>1,"Not current","Current"))) -> Current
A9: 8010 | B9: =IF(A9="","",IF(COUNTIFS(Data!$A$2:$A$501,A9)=1,INDEX(Data!$B$2:$B$501,MATCH(A9,Data!$A$2:$A$501,0)),"Not in current directory")) -> Abraham Lincoln High School | C9: No | J9: Not contacted | K9: Unknown | L9: =IF(A9="","",IF(COUNTIFS($A$8:$A$507,A9)<>1,"Duplicate ID",IF(COUNTIFS(Data!$A$2:$A$501,A9)<>1,"Not current","Current"))) -> Current
A10: 2520 | B10: =IF(A10="","",IF(COUNTIFS(Data!$A$2:$A$501,A10)=1,INDEX(Data!$B$2:$B$501,MATCH(A10,Data!$A$2:$A$501,0)),"Not in current directory")) -> Abram S. Jenks School | C10: No | J10: Not contacted | K10: Unknown | L10: =IF(A10="","",IF(COUNTIFS($A$8:$A$507,A10)<>1,"Duplicate ID",IF(COUNTIFS(Data!$A$2:$A$501,A10)<>1,"Not current","Current"))) -> Current
